DEBUG:shapely.geos:Found GEOS DLL: <CDLL '/home/gossq/.local/lib/python3.9/site-packages/Shapely.libs/libgeos_c-c8ec7514.so.1.16.1', handle 225fc50 at 0x7f32643cb910>, using it.
DEBUG:shapely.geos:Found GEOS DLL: <CDLL '/home/gossq/.local/lib/python3.9/site-packages/Shapely.libs/libgeos_c-c8ec7514.so.1.16.1', handle 29b3da0 at 0x7f6f5df41910>, using it.
DEBUG:shapely.geos:Found GEOS DLL: <CDLL '/home/gossq/.local/lib/python3.9/site-packages/Shapely.libs/libgeos_c-c8ec7514.so.1.16.1', handle 30a2da0 at 0x7ffafbb5d910>, using it.
DEBUG:shapely.geos:Found GEOS DLL: <CDLL '/home/gossq/.local/lib/python3.9/site-packages/Shapely.libs/libgeos_c-c8ec7514.so.1.16.1', handle 307dda0 at 0x7f8a98a03910>, using it.
ERROR:root:Exception caught at runtime...
Traceback (most recent call last):
  File "/home/gossq/git-projects/scenic-sumo-gui/gui.py", line 94, in __init__
    self.run()
  File "/home/gossq/git-projects/scenic-sumo-gui/gui.py", line 132, in run
    simulator.createSimulation()
  File "/home/gossq/.local/lib/python3.9/site-packages/scenic/simulators/sumo/simulator.py", line 145, in createSimulation
    sim = SumoSimulation(
  File "/home/gossq/.local/lib/python3.9/site-packages/scenic/simulators/sumo/simulator.py", line 195, in __init__
    self.__iterateScene(self._scene)
  File "/home/gossq/.local/lib/python3.9/site-packages/scenic/simulators/sumo/simulator.py", line 408, in __iterateScene
    self.__createCar(count, scenicObj)
  File "/home/gossq/.local/lib/python3.9/site-packages/scenic/simulators/sumo/simulator.py", line 432, in __createCar
    traci.route.add(trip, scenicObj.route)
  File "/home/gossq/.local/lib/python3.9/site-packages/traci/_route.py", line 43, in add
    self._setCmd(tc.ADD, routeID, "l", edges)
  File "/home/gossq/.local/lib/python3.9/site-packages/traci/domain.py", line 164, in _setCmd
    self._connection._sendCmd(self._cmdSetID, varID, objectID, format, *values)
  File "/home/gossq/.local/lib/python3.9/site-packages/traci/connection.py", line 225, in _sendCmd
    return self._sendExact()
  File "/home/gossq/.local/lib/python3.9/site-packages/traci/connection.py", line 142, in _sendExact
    raise TraCIException(err, prefix[1], _RESULTS[prefix[2]])
traci.exceptions.TraCIException: Unknown edge 'E8' in route.
